Workbook
Name _xlcn.WorksheetConnection_Tvisha_Jewlz_Intern_Assignment_Raw_Data.xlsxTable11: Table1[]
Name _xlcn.WorksheetConnection_Tvisha_Jewlz_Intern_Assignment_Raw_Data.xlsxTable131: Table13[]
Name _xlcn.WorksheetConnection_Tvisha_Jewlz_Intern_Assignment_Raw_Data.xlsxTable4471: Table447[]
Name Slicer_City1: #REF!
Name Slicer_Follow_up_Status1: #REF!
Name _xlcn.WorksheetConnection_Workingsheet2H4H101: 'Working sheet 2'!$H$4:$H$10

Sheet Problem Statement

Sheet Original Sheet
A1: Customer Name | B1: Phone Number | C1: City | D1: Piece of Interest | E1: Follow-up Status | F1: Last Follow-up Date | G1: Remarks | H1: Valid Phone | I1: Column1
A2: Customer 7 | B2: +91981207197 | C2: Hyderabad | D2: Diamond Ring | E2: Closed | F2: 23-08-2025 | G2: low budget | H2: =IF(LEN(TRIM(A2))=10,"Valid","Invalid") -> Valid
A3: Customer 11 | B3: 316699969071 | C3: Delhi | D3: Bridal Set | E3: Not Responded | F3: 19-08-2025 | G3: low budget | H3: =IF(LEN(TRIM(A3))=10,"Valid","Invalid") -> Invalid
A4: Customer 15 | B4: 07555537329 | C4: Jaipur | D4: Jadau Earrings | E4: Appointment Fixed | F4: 18-08-2025 | G4: low budget | H4: =IF(LEN(TRIM(A4))=10,"Valid","Invalid") -> Invalid
A5: Customer 16 | B5: +91924004015 | C5: Hyd | D5: Bridal Set | E5: Closed | F5: 23-08-2025 | G5: Wants Callback | H5: =IF(LEN(TRIM(A5))=10,"Valid","Invalid") -> Invalid
A6: Customer 7 | B6: 07167705031 | C6: Mumabi | D6: Jadau Earrings | E6: Contacted | F6: 23-08-2025 | G6: low budget | H6: =IF(LEN(TRIM(A6))=10,"Valid","Invalid") -> Valid
A7: Customer 9 | B7: 07326304605 | C7: Jaipur | D7: Jadau Earrings | E7: Not Responded | F7: 25-08-2025 | G7: interested | H7: =IF(LEN(TRIM(A7))=10,"Valid","Invalid") -> Valid
A8: Customer 5 | B8: +917452200799 | C8: Mumbai | D8: Polki Necklace | E8: Pending | F8: 18-08-2025 | G8: High Budget | H8: =IF(LEN(TRIM(A8))=10,"Valid","Invalid") -> Valid
A9: Customer 2 | B9: 366479543551 | C9: Hyderabad | D9: Diamond Ring | E9: Contacted | F9: 22-08-2025 | G9: High Budget | H9: =IF(LEN(TRIM(A9))=10,"Valid","Invalid") -> Valid
A10: Customer 25 | B10: +917238138275 | C10: Jaipur | D10: Diamond Ring | E10: Pending | F10: 18-08-2025 | G10: Comparing Options | H10: =IF(LEN(TRIM(A10))=10,"Valid","Invalid") -> Invalid
A11: Customer 2 | B11: 294307938915 | C11: Bangalore | D11: Diamond Ring | E11: Appointment Fixed | F11: 16-08-2025 | G11: Comparing Options | H11: =IF(LEN(TRIM(A11))=10,"Valid","Invalid") -> Valid
A12: Customer 16 | B12: 07719529297 | C12: Hyd | D12: Polki Necklace | E12: Closed | F12: 16-08-2025 | G12: High Budget | H12: =IF(LEN(TRIM(A12))=10,"Valid","Invalid") -> Invalid
A13: Customer 16 | B13: 237172709909 | C13: Mumabi | D13: Gold Bangles | E13: Pending | F13: 17-08-2025 | G13: Wants Callback | H13: =IF(LEN(TRIM(A13))=10,"Valid","Invalid") -> Invalid
A14: Customer 7 | B14: +91 9654384657 | C14: Delhi | D14: Gold Bangles | E14: Contacted | F14: 18-08-2025 | G14: Comparing Options | H14: =IF(LEN(TRIM(A14))=10,"Valid","Invalid") -> Valid
A15: Customer 8 | B15: 117040380882 | C15: Bangalore | D15: Gold Bangles | E15: Closed | F15: 18-08-2025 | G15: Comparing Options | H15: =IF(LEN(TRIM(A15))=10,"Valid","Invalid") -> Valid | I15: O
A16: Customer 2 | B16: +91 8676078088 | C16: Mumbai | D16: Diamond Ring | E16: Contacted | F16: 22-08-2025 | G16: Interested | H16: =IF(LEN(TRIM(A16))=10,"Valid","Invalid") -> Valid
A17: Customer 1 | B17: +918321936663 | C17: Hyderabad | D17: Bridal Set | E17: Not Responded | F17: 18-08-2025 | G17: Wants Callback | H17: =IF(LEN(TRIM(A17))=10,"Valid","Invalid") -> Valid
A18: Customer 1 | B18: 969140392131 | C18: Hyd | D18: Polki Necklace | E18: Closed | F18: 16-08-2025 | G18: low budget | H18: =IF(LEN(TRIM(A18))=10,"Valid","Invalid") -> Valid
A19: Customer 16 | B19: +917541729247 | C19: Hyd | D19: Diamond Ring | E19: Pending | F19: 21-08-2025 | G19: Wants Callback | H19: =IF(LEN(TRIM(A19))=10,"Valid","Invalid") -> Invalid
A20: Customer 6 | B20: 09411182015 | C20: Jaipur | D20: Gold Bangles | E20: Not Responded | F20: 25-08-2025 | G20: Wants Callback | H20: =IF(LEN(TRIM(A20))=10,"Valid","Invalid") -> Valid
A21: Customer 21 | B21: 184634638538 | C21: Bengluru | D21: Diamond Ring | E21: Closed | G21: Wants Callback | H21: =IF(LEN(TRIM(A21))=10,"Valid","Invalid") -> Invalid
A22: Customer 20 | B22: 07857711890 | C22: Mumbai | D22: Jadau Earrings | E22: Contacted | F22: 15-08-2025 | G22: Comparing Options | H22: =IF(LEN(TRIM(A22))=10,"Valid","Invalid") -> Invalid
A23: Customer 11 | B23: +919705030412 | C23: Delhi | D23: Bridal Set | E23: Pending | F23: 15-08-2025 | G23: Wants Callback | H23: =IF(LEN(TRIM(A23))=10,"Valid","Invalid") -> Invalid
A24: Customer 6 | B24: +91890030316 | C24: Mumabi | D24: Jadau Earrings | E24: Contacted | F24: 23-08-2025 | G24: Comparing Options | H24: =IF(LEN(TRIM(A24))=10,"Valid","Invalid") -> Valid
A25: Customer 5 | B25: +91 9426142443 | C25: Hyderabad | D25: Jadau Earrings | E25: Contacted | F25: 21-08-2025 | G25: Interested | H25: =IF(LEN(TRIM(A25))=10,"Valid","Invalid") -> Valid
A26: Customer 6 | B26: +91805352028 | C26: Mumbai | D26: Polki Necklace | E26: Closed | F26: 22-08-2025 | G26: High Budget | H26: =IF(LEN(TRIM(A26))=10,"Valid","Invalid") -> Valid
A27: Customer 22 | B27: +918966036820 | C27: Delhi | D27: Jadau Earrings | E27: Pending | F27: 25-08-2025 | G27: low budget | H27: =IF(LEN(TRIM(A27))=10,"Valid","Invalid") -> Invalid
A28: Customer 9 | B28: +91 8890833782 | C28: Delhi | D28: Gold Bangles | E28: Contacted | F28: 19-08-2025 | G28: Comparing Options | H28: =IF(LEN(TRIM(A28))=10,"Valid","Invalid") -> Valid
A29: Customer 25 | B29: +91969752546 | C29: Delhi | D29: Diamond Ring | E29: Closed | F29: 21-08-2025 | G29: High Budget | H29: =IF(LEN(TRIM(A29))=10,"Valid","Invalid") -> Invalid
A30: Customer 25 | B30: 07752644151 | C30: Hyd | D30: Bridal Set | E30: Closed | F30: 22-08-2025 | G30: Interested | H30: =IF(LEN(TRIM(A30))=10,"Valid","Invalid") -> Invalid
A31: Customer 1 | B31: +91705363184 | C31: Jaipur | D31: Jadau Earrings | E31: Pending | F31: 23-08-2025 | G31: Comparing Options | H31: =IF(LEN(TRIM(A31))=10,"Valid","Invalid") -> Valid
A32: Customer 24 | B32: +91927038743 | C32: Hyd | D32: Gold Bangles | E32: Not Responded | F32: 18-08-2025 | G32: Interested | H32: =IF(LEN(TRIM(A32))=10,"Valid","Invalid") -> Invalid
A33: Customer 5 | B33: 08057410309 | C33: Mumbai | D33: Jadau Earrings | E33: Pending | G33: interested | H33: =IF(LEN(TRIM(A33))=10,"Valid","Invalid") -> Valid
A34: Customer 1 | B34: 09256072034 | C34: Mumbai | D34: Polki Necklace | E34: Contacted | F34: 16-08-2025 | G34: interested | H34: =IF(LEN(TRIM(A34))=10,"Valid","Invalid") -> Valid
A35: Customer 3 | B35: +91879307780 | C35: Mumbai | D35: Jadau Earrings | E35: Closed | F35: 23-08-2025 | G35: High Budget | H35: =IF(LEN(TRIM(A35))=10,"Valid","Invalid") -> Valid
A36: Customer 12 | B36: 08132565651 | C36: Mumbai | D36: Polki Necklace | E36: Not Responded | G36: Comparing Options | H36: =IF(LEN(TRIM(A36))=10,"Valid","Invalid") -> Invalid

Sheet Working sheet 1
A1: Lead_ID | B1: Customer Name | C1: Phone number | D1: Phone status | E1: City | F1: Piece of Interest | G1: Follow-up Status | H1: Last Follow-up Date | I1: Remarks
A2: =_xlfn.CONCAT(Table13[[#This Row],[Customer Name]]," - ",Table13[[#This Row],[Phone number]]) -> #ERROR! | B2: Customer 7 | C2: 981207197 | D2: =IF(LEN(C2)<>10,"invalid","valid") -> invalid | E2: Hyderabad | F2: Diamond Ring | G2: Closed | H2: 23-08-2025 | I2: Low Budget
A3: =_xlfn.CONCAT(Table13[[#This Row],[Customer Name]]," - ",Table13[[#This Row],[Phone number]]) -> #ERROR! | B3: Customer 11 | C3: 316699969071 | D3: =IF(LEN(C3)<>10,"invalid","valid") -> invalid | E3: Delhi | F3: Bridal Set | G3: Not Responded | H3: 19-08-2025 | I3: Low Budget
A4: =_xlfn.CONCAT(Table13[[#This Row],[Customer Name]]," - ",Table13[[#This Row],[Phone number]]) -> #ERROR! | B4: Customer 15 | C4: 07555537329 | D4: =IF(LEN(C4)<>10,"invalid","valid") -> invalid | E4: Jaipur | F4: Jadau Earrings | G4: Appointment Fixed | H4: 18-08-2025 | I4: Low Budget
A5: =_xlfn.CONCAT(Table13[[#This Row],[Customer Name]]," - ",Table13[[#This Row],[Phone number]]) -> #ERROR! | B5: Customer 16 | C5: 924004015 | D5: =IF(LEN(C5)<>10,"invalid","valid") -> invalid | E5: Hyderabad | F5: Bridal Set | G5: Closed | H5: 23-08-2025 | I5: Wants Callback
A6: =_xlfn.CONCAT(Table13[[#This Row],[Customer Name]]," - ",Table13[[#This Row],[Phone number]]) -> #ERROR! | B6: Customer 7 | C6: 07167705031 | D6: =IF(LEN(C6)<>10,"invalid","valid") -> invalid | E6: Mumbai | F6: Jadau Earrings | G6: Contacted | H6: 23-08-2025 | I6: Low Budget
A7: =_xlfn.CONCAT(Table13[[#This Row],[Customer Name]]," - ",Table13[[#This Row],[Phone number]]) -> #ERROR! | B7: Customer 9 | C7: 07326304605 | D7: =IF(LEN(C7)<>10,"invalid","valid") -> invalid | E7: Jaipur | F7: Jadau Earrings | G7: Not Responded | H7: 25-08-2025 | I7: Interested
A8: =_xlfn.CONCAT(Table13[[#This Row],[Customer Name]]," - ",Table13[[#This Row],[Phone number]]) -> #ERROR! | B8: Customer 5 | C8: 7452200799 | D8: =IF(LEN(C8)<>10,"invalid","valid") -> valid | E8: Mumbai | F8: Polki Necklace | G8: Pending | H8: 18-08-2025 | I8: High Budget
A9: =_xlfn.CONCAT(Table13[[#This Row],[Customer Name]]," - ",Table13[[#This Row],[Phone number]]) -> #ERROR! | B9: Customer 2 | C9: 366479543551 | D9: =IF(LEN(C9)<>10,"invalid","valid") -> invalid | E9: Hyderabad | F9: Diamond Ring | G9: Contacted | H9: 22-08-2025 | I9: High Budget
A10: =_xlfn.CONCAT(Table13[[#This Row],[Customer Name]]," - ",Table13[[#This Row],[Phone number]]) -> #ERROR! | B10: Customer 25 | C10: 7238138275 | D10: =IF(LEN(C10)<>10,"invalid","valid") -> valid | E10: Jaipur | F10: Diamond Ring | G10: Pending | H10: 18-08-2025 | I10: Comparing Options
A11: =_xlfn.CONCAT(Table13[[#This Row],[Customer Name]]," - ",Table13[[#This Row],[Phone number]]) -> #ERROR! | B11: Customer 2 | C11: 294307938915 | D11: =IF(LEN(C11)<>10,"invalid","valid") -> invalid | E11: Bangalore | F11: Diamond Ring | G11: Appointment Fixed | H11: 16-08-2025 | I11: Comparing Options
A12: =_xlfn.CONCAT(Table13[[#This Row],[Customer Name]]," - ",Table13[[#This Row],[Phone number]]) -> #ERROR! | B12: Customer 16 | C12: 07719529297 | D12: =IF(LEN(C12)<>10,"invalid","valid") -> invalid | E12: Hyderabad | F12: Polki Necklace | G12: Closed | H12: 16-08-2025 | I12: High Budget
A13: =_xlfn.CONCAT(Table13[[#This Row],[Customer Name]]," - ",Table13[[#This Row],[Phone number]]) -> #ERROR! | B13: Customer 16 | C13: 237172709909 | D13: =IF(LEN(C13)<>10,"invalid","valid") -> invalid | E13: Mumbai | F13: Gold Bangles | G13: Pending | H13: 17-08-2025 | I13: Wants Callback
A14: =_xlfn.CONCAT(Table13[[#This Row],[Customer Name]]," - ",Table13[[#This Row],[Phone number]]) -> #ERROR! | B14: Customer 7 | C14: 9654384657 | D14: =IF(LEN(C14)<>10,"invalid","valid") -> valid | E14: Delhi | F14: Gold Bangles | G14: Contacted | H14: 18-08-2025 | I14: Comparing Options
A15: =_xlfn.CONCAT(Table13[[#This Row],[Customer Name]]," - ",Table13[[#This Row],[Phone number]]) -> #ERROR! | B15: Customer 8 | C15: 117040380882 | D15: =IF(LEN(C15)<>10,"invalid","valid") -> invalid | E15: Bangalore | F15: Gold Bangles | G15: Closed | H15: 18-08-2025 | I15: Comparing Options
... A36: =_xlfn.CONCAT(Table13[[#This Row],[Customer Name]]," - ",Table13[[#This Row],[Phone number]]) -> #ERROR! | B36: Customer 12 | C36: 08132565651 | D36: =IF(LEN(C36)<>10,"invalid","valid") -> invalid | E36: Mumbai | F36: Polki Necklace | G36: Not Responded | H36: Not Updated | I36: Comparing Options
D37: =IF(LEN(C37)<>10,"invalid","valid") -> invalid

Sheet Cleaned_Data
A1: Lead_ID | B1: Customer Name | C1: Phone number | D1: Phone status-flag | E1: City | F1: Piece of Interest | G1: Follow-up Status | H1: Last Follow-up Date | I1: Remarks
A2: Customer 7 - 981207197 | B2: Customer 7 | C2: 981207197 | D2: invalid | E2: Hyderabad | F2: Diamond Ring | G2: Closed | H2: 23-08-2025 | I2: Low Budget
A3: Customer 11 - 316699969071 | B3: Customer 11 | C3: 316699969071 | D3: invalid | E3: Delhi | F3: Bridal Set | G3: Not Responded | H3: 19-08-2025 | I3: Low Budget
A4: Customer 15 - 07555537329 | B4: Customer 15 | C4: 07555537329 | D4: invalid | E4: Jaipur | F4: Jadau Earrings | G4: Appointment Fixed | H4: 18-08-2025 | I4: Low Budget
A5: Customer 16 - 924004015 | B5: Customer 16 | C5: 924004015 | D5: invalid | E5: Hyderabad | F5: Bridal Set | G5: Closed | H5: 23-08-2025 | I5: Wants Callback
A6: Customer 7 - 07167705031 | B6: Customer 7 | C6: 07167705031 | D6: invalid | E6: Mumbai | F6: Jadau Earrings | G6: Contacted | H6: 23-08-2025 | I6: Low Budget
A7: Customer 9 - 07326304605 | B7: Customer 9 | C7: 07326304605 | D7: invalid | E7: Jaipur | F7: Jadau Earrings | G7: Not Responded | H7: 25-08-2025 | I7: Interested
A8: Customer 5 - 7452200799 | B8: Customer 5 | C8: 7452200799 | D8: valid | E8: Mumbai | F8: Polki Necklace | G8: Pending | H8: 18-08-2025 | I8: High Budget
A9: Customer 2 - 366479543551 | B9: Customer 2 | C9: 366479543551 | D9: invalid | E9: Hyderabad | F9: Diamond Ring | G9: Contacted | H9: 22-08-2025 | I9: High Budget
A10: Customer 25 - 7238138275 | B10: Customer 25 | C10: 7238138275 | D10: valid | E10: Jaipur | F10: Diamond Ring | G10: Pending | H10: 18-08-2025 | I10: Comparing Options
A11: Customer 2 - 294307938915 | B11: Customer 2 | C11: 294307938915 | D11: invalid | E11: Bangalore | F11: Diamond Ring | G11: Appointment Fixed | H11: 16-08-2025 | I11: Comparing Options
A12: Customer 16 - 07719529297 | B12: Customer 16 | C12: 07719529297 | D12: invalid | E12: Hyderabad | F12: Polki Necklace | G12: Closed | H12: 16-08-2025 | I12: High Budget
A13: Customer 16 - 237172709909 | B13: Customer 16 | C13: 237172709909 | D13: invalid | E13: Mumbai | F13: Gold Bangles | G13: Pending | H13: 17-08-2025 | I13: Wants Callback
A14: Customer 7 - 9654384657 | B14: Customer 7 | C14: 9654384657 | D14: valid | E14: Delhi | F14: Gold Bangles | G14: Contacted | H14: 18-08-2025 | I14: Comparing Options
A15: Customer 8 - 117040380882 | B15: Customer 8 | C15: 117040380882 | D15: invalid | E15: Bangalore | F15: Gold Bangles | G15: Closed | H15: 18-08-2025 | I15: Comparing Options
... A36: Customer 12 - 08132565651 | B36: Customer 12 | C36: 08132565651 | D36: invalid | E36: Mumbai | F36: Polki Necklace | G36: Not Responded | H36: Not Updated | I36: Comparing Options

Sheet Working sheet 2
O1: Follow-up status pending for more than 5 days
O2: Lead_ID | P2: Follow-up Status | Q2: Days Since Last Follow-up | R2: =S17 | U2: Lead_ID | V2: Follow-up Status | W2: Remarks | X2: Follow-up status flag
O3: Customer 7 - 981207197 | P3: Closed | Q3: 69 | R3: =IF(AND(Cleaned_Data!I3="Interested",Cleaned_Data!G3="Not Responded"),"Interested but not responded") -> FALSE | U3: Customer 7 - 981207197 | V3: Closed | W3: Low Budget | X3: =IF(AND(W3="Interested",V3="Not Responded"),"Interested but not responded","Nil") -> Nil
B4: No. of Leads per city | E4: No. of Leads by Follow-up Status | H4: % Conversion Rate per city | K4: Days Since Last Follow-up | O4: Customer 11 - 316699969071 | P4: Not Responded | Q4: 73 | R4: =IF(AND(Cleaned_Data!I4="Interested",Cleaned_Data!G4="Not Responded"),"Interested but not responded") -> FALSE | U4: Customer 11 - 316699969071 | V4: Not Responded | W4: Low Budget | X4: =IF(AND(W4="Interested",V4="Not Responded"),"Interested but not responded","Nil") -> Nil
H5: City | I5: % Conversion Rate | O5: Customer 15 - 07555537329 | P5: Appointment Fixed | Q5: 74 | R5: =IF(AND(Cleaned_Data!I5="Interested",Cleaned_Data!G5="Not Responded"),"Interested but not responded") -> FALSE | U5: Customer 15 - 07555537329 | V5: Appointment Fixed | W5: Low Budget | X5: =IF(AND(W5="Interested",V5="Not Responded"),"Interested but not responded","Nil") -> Nil
B6: City | C6: No. of leads | E6: Follow-up Status | F6: No. of Leads | H6: {=UNIQUE(Cleaned_Data!E2:E36,FALSE,FALSE)} -> Hyderabad | I6: =COUNTIFS(Cleaned_Data!E:E,'Working sheet 2'!H6,Cleaned_Data!G:G,"Closed")/COUNTIF(Cleaned_Data!E:E,'Working sheet 2'!H6) -> 0.5 | K6: Customer name | L6: Days Since Last Follow-up | O6: Customer 16 - 924004015 | P6: Closed | Q6: 69 | R6: =IF(AND(Cleaned_Data!I6="Interested",Cleaned_Data!G6="Not Responded"),"Interested but not responded") -> FALSE | U6: Customer 16 - 924004015 | V6: Closed | W6: Wants Callback | X6: =IF(AND(W6="Interested",V6="Not Responded"),"Interested but not responded","Nil") -> Nil
B7: {=UNIQUE(Cleaned_Data!E2:E36,FALSE,FALSE)} -> Hyderabad | C7: =COUNTIF(Cleaned_Data!E2:E36,'Working sheet 2'!B7) -> 10 | E7: {=UNIQUE(Cleaned_Data!G2:G36,FALSE,FALSE)} -> Closed | F7: =COUNTIF(Cleaned_Data!G2:G36,'Working sheet 2'!E7) -> 10 | H7: Delhi | I7: =COUNTIFS(Cleaned_Data!E:E,'Working sheet 2'!H7,Cleaned_Data!G:G,"Closed")/COUNTIF(Cleaned_Data!E:E,'Working sheet 2'!H7) -> 0.16666667 | K7: Customer 7 | L7: =IFERROR(TODAY()-Cleaned_Data!H2,"not_updated") -> 258 | O7: Customer 7 - 07167705031 | P7: Contacted | Q7: 69 | R7: =IF(AND(Cleaned_Data!I7="Interested",Cleaned_Data!G7="Not Responded"),"Interested but not responded") -> Interested but not responded | U7: Customer 7 - 07167705031 | V7: Contacted | W7: Low Budget | X7: =IF(AND(W7="Interested",V7="Not Responded"),"Interested but not responded","Nil") -> Nil
B8: Delhi | C8: =COUNTIF(Cleaned_Data!E3:E37,'Working sheet 2'!B8) -> 6 | E8: Not Responded | F8: =COUNTIF(Cleaned_Data!G3:G37,'Working sheet 2'!E8) -> 6 | H8: Jaipur | I8: =COUNTIFS(Cleaned_Data!E:E,'Working sheet 2'!H8,Cleaned_Data!G:G,"Closed")/COUNTIF(Cleaned_Data!E:E,'Working sheet 2'!H8) -> 0 | K8: Customer 11 | L8: =IFERROR(TODAY()-Cleaned_Data!H3,"not_updated") -> 262 | O8: Customer 9 - 07326304605 | P8: Not Responded | Q8: 67 | R8: =IF(AND(Cleaned_Data!I8="Interested",Cleaned_Data!G8="Not Responded"),"Interested but not responded") -> FALSE | U8: Customer 9 - 07326304605 | V8: Not Responded | W8: Interested | X8: =IF(AND(W8="Interested",V8="Not Responded"),"Interested but not responded","Nil") -> Interested but not responded
B9: Jaipur | C9: =COUNTIF(Cleaned_Data!E4:E38,'Working sheet 2'!B9) -> 5 | E9: Appointment Fixed | F9: =COUNTIF(Cleaned_Data!G4:G38,'Working sheet 2'!E9) -> 2 | H9: Mumbai | I9: =COUNTIFS(Cleaned_Data!E:E,'Working sheet 2'!H9,Cleaned_Data!G:G,"Closed")/COUNTIF(Cleaned_Data!E:E,'Working sheet 2'!H9) -> 0.18181818 | K9: Customer 15 | L9: =IFERROR(TODAY()-Cleaned_Data!H4,"not_updated") -> 263 | O9: Customer 5 - 7452200799 | P9: Pending | Q9: 74 | R9: =IF(AND(Cleaned_Data!I9="Interested",Cleaned_Data!G9="Not Responded"),"Interested but not responded") -> FALSE | U9: Customer 5 - 7452200799 | V9: Pending | W9: High Budget | X9: =IF(AND(W9="Interested",V9="Not Responded"),"Interested but not responded","Nil") -> Nil
B10: Mumbai | C10: =COUNTIF(Cleaned_Data!E5:E39,'Working sheet 2'!B10) -> 11 | E10: Contacted | F10: =COUNTIF(Cleaned_Data!G5:G39,'Working sheet 2'!E10) -> 9 | H10: Bangalore | I10: =COUNTIFS(Cleaned_Data!E:E,'Working sheet 2'!H10,Cleaned_Data!G:G,"Closed")/COUNTIF(Cleaned_Data!E:E,'Working sheet 2'!H10) -> 0.66666667 | K10: Customer 16 | L10: =IFERROR(TODAY()-Cleaned_Data!H5,"not_updated") -> 258 | O10: Customer 2 - 366479543551 | P10: Contacted | Q10: 70 | R10: =IF(AND(Cleaned_Data!I10="Interested",Cleaned_Data!G10="Not Responded"),"Interested but not responded") -> FALSE | U10: Customer 2 - 366479543551 | V10: Contacted | W10: High Budget | X10: =IF(AND(W10="Interested",V10="Not Responded"),"Interested but not responded","Nil") -> Nil
B11: Bangalore | C11: =COUNTIF(Cleaned_Data!E6:E40,'Working sheet 2'!B11) -> 3 | E11: Pending | F11: =COUNTIF(Cleaned_Data!G6:G40,'Working sheet 2'!E11) -> 8 | K11: Customer 7 | L11: =IFERROR(TODAY()-Cleaned_Data!H6,"not_updated") -> 258 | O11: Customer 25 - 7238138275 | P11: Pending | Q11: 74 | R11: =IF(AND(Cleaned_Data!I11="Interested",Cleaned_Data!G11="Not Responded"),"Interested but not responded") -> FALSE | U11: Customer 25 - 7238138275 | V11: Pending | W11: Comparing Options | X11: =IF(AND(W11="Interested",V11="Not Responded"),"Interested but not responded","Nil") -> Nil
K12: Customer 9 | L12: =IFERROR(TODAY()-Cleaned_Data!H7,"not_updated") -> 256 | O12: Customer 2 - 294307938915 | P12: Appointment Fixed | Q12: 76 | R12: =IF(AND(Cleaned_Data!I12="Interested",Cleaned_Data!G12="Not Responded"),"Interested but not responded") -> FALSE | U12: Customer 2 - 294307938915 | V12: Appointment Fixed | W12: Comparing Options | X12: =IF(AND(W12="Interested",V12="Not Responded"),"Interested but not responded","Nil") -> Nil
K13: Customer 5 | L13: =IFERROR(TODAY()-Cleaned_Data!H8,"not_updated") -> 263 | O13: Customer 16 - 07719529297 | P13: Closed | Q13: 76 | R13: =IF(AND(Cleaned_Data!I13="Interested",Cleaned_Data!G13="Not Responded"),"Interested but not responded") -> FALSE | U13: Customer 16 - 07719529297 | V13: Closed | W13: High Budget | X13: =IF(AND(W13="Interested",V13="Not Responded"),"Interested but not responded","Nil") -> Nil
K14: Customer 2 | L14: =IFERROR(TODAY()-Cleaned_Data!H9,"not_updated") -> 259 | O14: Customer 16 - 237172709909 | P14: Pending | Q14: 75 | R14: =IF(AND(Cleaned_Data!I14="Interested",Cleaned_Data!G14="Not Responded"),"Interested but not responded") -> FALSE | U14: Customer 16 - 237172709909 | V14: Pending | W14: Wants Callback | X14: =IF(AND(W14="Interested",V14="Not Responded"),"Interested but not responded","Nil") -> Nil
K15: Customer 25 | L15: =IFERROR(TODAY()-Cleaned_Data!H10,"not_updated") -> 263 | O15: Customer 7 - 9654384657 | P15: Contacted | Q15: 74 | R15: =IF(AND(Cleaned_Data!I15="Interested",Cleaned_Data!G15="Not Responded"),"Interested but not responded") -> FALSE | U15: Customer 7 - 9654384657 | V15: Contacted | W15: Comparing Options | X15: =IF(AND(W15="Interested",V15="Not Responded"),"Interested but not responded","Nil") -> Nil
K16: Customer 2 | L16: =IFERROR(TODAY()-Cleaned_Data!H11,"not_updated") -> 265 | O16: Customer 8 - 117040380882 | P16: Closed | Q16: 74 | R16: =IF(AND(Cleaned_Data!I16="Interested",Cleaned_Data!G16="Not Responded"),"Interested but not responded") -> FALSE | U16: Customer 8 - 117040380882 | V16: Closed | W16: Comparing Options | X16: =IF(AND(W16="Interested",V16="Not Responded"),"Interested but not responded","Nil") -> Nil
K17: Customer 16 | L17: =IFERROR(TODAY()-Cleaned_Data!H12,"not_updated") -> 265 | O17: Customer 2 - 8676078088 | P17: Contacted | Q17: 70 | R17: =IF(AND(Cleaned_Data!I17="Interested",Cleaned_Data!G17="Not Responded"),"Interested but not responded") -> FALSE | U17: Customer 2 - 8676078088 | V17: Contacted | W17: Interested | X17: =IF(AND(W17="Interested",V17="Not Responded"),"Interested but not responded","Nil") -> Nil
K18: Customer 16 | L18: =IFERROR(TODAY()-Cleaned_Data!H13,"not_updated") -> 264 | O18: Customer 1 - 8321936663 | P18: Not Responded | Q18: 74 | R18: =IF(AND(Cleaned_Data!I18="Interested",Cleaned_Data!G18="Not Responded"),"Interested but not responded") -> FALSE | U18: Customer 1 - 8321936663 | V18: Not Responded | W18: Wants Callback | X18: =IF(AND(W18="Interested",V18="Not Responded"),"Interested but not responded","Nil") -> Nil
K19: Customer 7 | L19: =IFERROR(TODAY()-Cleaned_Data!H14,"not_updated") -> 263 | O19: Customer 1 - 969140392131 | P19: Closed | Q19: 76 | R19: =IF(AND(Cleaned_Data!I19="Interested",Cleaned_Data!G19="Not Responded"),"Interested but not responded") -> FALSE | U19: Customer 1 - 969140392131 | V19: Closed | W19: Low Budget | X19: =IF(AND(W19="Interested",V19="Not Responded"),"Interested but not responded","Nil") -> Nil
K20: Customer 8 | L20: =IFERROR(TODAY()-Cleaned_Data!H15,"not_updated") -> 263 | O20: Customer 16 - 7541729247 | P20: Pending | Q20: 71 | R20: =IF(AND(Cleaned_Data!I20="Interested",Cleaned_Data!G20="Not Responded"),"Interested but not responded") -> FALSE | U20: Customer 16 - 7541729247 | V20: Pending | W20: Wants Callback | X20: =IF(AND(W20="Interested",V20="Not Responded"),"Interested but not responded","Nil") -> Nil
K21: Customer 2 | L21: =IFERROR(TODAY()-Cleaned_Data!H16,"not_updated") -> 259 | O21: Customer 6 - 09411182015 | P21: Not Responded | Q21: 67 | R21: =IF(AND(Cleaned_Data!I21="Interested",Cleaned_Data!G21="Not Responded"),"Interested but not responded") -> FALSE | U21: Customer 6 - 09411182015 | V21: Not Responded | W21: Wants Callback | X21: =IF(AND(W21="Interested",V21="Not Responded"),"Interested but not responded","Nil") -> Nil
K22: Customer 1 | L22: =IFERROR(TODAY()-Cleaned_Data!H17,"not_updated") -> 263 | O22: Customer 21 - 184634638538 | P22: Closed | Q22: not_updated | R22: =IF(AND(Cleaned_Data!I22="Interested",Cleaned_Data!G22="Not Responded"),"Interested but not responded") -> FALSE | U22: Customer 21 - 184634638538 | V22: Closed | W22: Wants Callback | X22: =IF(AND(W22="Interested",V22="Not Responded"),"Interested but not responded","Nil") -> Nil
K23: Customer 1 | L23: =IFERROR(TODAY()-Cleaned_Data!H18,"not_updated") -> 265 | O23: Customer 20 - 07857711890 | P23: Contacted | Q23: 77 | R23: =IF(AND(Cleaned_Data!I23="Interested",Cleaned_Data!G23="Not Responded"),"Interested but not responded") -> FALSE | U23: Customer 20 - 07857711890 | V23: Contacted | W23: Comparing Options | X23: =IF(AND(W23="Interested",V23="Not Responded"),"Interested but not responded","Nil") -> Nil
K24: Customer 16 | L24: =IFERROR(TODAY()-Cleaned_Data!H19,"not_updated") -> 260 | O24: Customer 11 - 9705030412 | P24: Pending | Q24: 77 | R24: =IF(AND(Cleaned_Data!I24="Interested",Cleaned_Data!G24="Not Responded"),"Interested but not responded") -> FALSE | U24: Customer 11 - 9705030412 | V24: Pending | W24: Wants Callback | X24: =IF(AND(W24="Interested",V24="Not Responded"),"Interested but not responded","Nil") -> Nil
K25: Customer 6 | L25: =IFERROR(TODAY()-Cleaned_Data!H20,"not_updated") -> 256 | O25: Customer 6 - 890030316 | P25: Contacted | Q25: 69 | R25: =IF(AND(Cleaned_Data!I25="Interested",Cleaned_Data!G25="Not Responded"),"Interested but not responded") -> FALSE | U25: Customer 6 - 890030316 | V25: Contacted | W25: Comparing Options | X25: =IF(AND(W25="Interested",V25="Not Responded"),"Interested but not responded","Nil") -> Nil
K26: Customer 21 | L26: =IFERROR(TODAY()-Cleaned_Data!H21,"not_updated") -> not_updated | O26: Customer 5 - 9426142443 | P26: Contacted | Q26: 71 | R26: =IF(AND(Cleaned_Data!I26="Interested",Cleaned_Data!G26="Not Responded"),"Interested but not responded") -> FALSE | U26: Customer 5 - 9426142443 | V26: Contacted | W26: Interested | X26: =IF(AND(W26="Interested",V26="Not Responded"),"Interested but not responded","Nil") -> Nil
K27: Customer 20 | L27: =IFERROR(TODAY()-Cleaned_Data!H22,"not_updated") -> 266 | O27: Customer 6 - 805352028 | P27: Closed | Q27: 70 | R27: =IF(AND(Cleaned_Data!I27="Interested",Cleaned_Data!G27="Not Responded"),"Interested but not responded") -> FALSE | U27: Customer 6 - 805352028 | V27: Closed | W27: High Budget | X27: =IF(AND(W27="Interested",V27="Not Responded"),"Interested but not responded","Nil") -> Nil
K28: Customer 11 | L28: =IFERROR(TODAY()-Cleaned_Data!H23,"not_updated") -> 266 | O28: Customer 22 - 8966036820 | P28: Pending | Q28: 67 | R28: =IF(AND(Cleaned_Data!I28="Interested",Cleaned_Data!G28="Not Responded"),"Interested but not responded") -> FALSE | U28: Customer 22 - 8966036820 | V28: Pending | W28: Low Budget | X28: =IF(AND(W28="Interested",V28="Not Responded"),"Interested but not responded","Nil") -> Nil
K29: Customer 6 | L29: =IFERROR(TODAY()-Cleaned_Data!H24,"not_updated") -> 258 | O29: Customer 9 - 8890833782 | P29: Contacted | Q29: 73 | R29: =IF(AND(Cleaned_Data!I29="Interested",Cleaned_Data!G29="Not Responded"),"Interested but not responded") -> FALSE | U29: Customer 9 - 8890833782 | V29: Contacted | W29: Comparing Options | X29: =IF(AND(W29="Interested",V29="Not Responded"),"Interested but not responded","Nil") -> Nil
K30: Customer 5 | L30: =IFERROR(TODAY()-Cleaned_Data!H25,"not_updated") -> 260 | O30: Customer 25 - 969752546 | P30: Closed | Q30: 71 | R30: =IF(AND(Cleaned_Data!I30="Interested",Cleaned_Data!G30="Not Responded"),"Interested but not responded") -> FALSE | U30: Customer 25 - 969752546 | V30: Closed | W30: High Budget | X30: =IF(AND(W30="Interested",V30="Not Responded"),"Interested but not responded","Nil") -> Nil
K31: Customer 6 | L31: =IFERROR(TODAY()-Cleaned_Data!H26,"not_updated") -> 259 | O31: Customer 25 - 07752644151 | P31: Closed | Q31: 70 | R31: =IF(AND(Cleaned_Data!I31="Interested",Cleaned_Data!G31="Not Responded"),"Interested but not responded") -> FALSE | U31: Customer 25 - 07752644151 | V31: Closed | W31: Interested | X31: =IF(AND(W31="Interested",V31="Not Responded"),"Interested but not responded","Nil") -> Nil
K32: Customer 22 | L32: =IFERROR(TODAY()-Cleaned_Data!H27,"not_updated") -> 256 | O32: Customer 1 - 705363184 | P32: Pending | Q32: 69 | R32: =IF(AND(Cleaned_Data!I32="Interested",Cleaned_Data!G32="Not Responded"),"Interested but not responded") -> Interested but not responded | U32: Customer 1 - 705363184 | V32: Pending | W32: Comparing Options | X32: =IF(AND(W32="Interested",V32="Not Responded"),"Interested but not responded","Nil") -> Nil
K33: Customer 9 | L33: =IFERROR(TODAY()-Cleaned_Data!H28,"not_updated") -> 262 | O33: Customer 24 - 927038743 | P33: Not Responded | Q33: 74 | R33: =IF(AND(Cleaned_Data!I33="Interested",Cleaned_Data!G33="Not Responded"),"Interested but not responded") -> FALSE | U33: Customer 24 - 927038743 | V33: Not Responded | W33: Interested | X33: =IF(AND(W33="Interested",V33="Not Responded"),"Interested but not responded","Nil") -> Interested but not responded
K34: Customer 25 | L34: =IFERROR(TODAY()-Cleaned_Data!H29,"not_updated") -> 260 | O34: Customer 5 - 08057410309 | P34: Pending | Q34: not_updated | R34: =IF(AND(Cleaned_Data!I34="Interested",Cleaned_Data!G34="Not Responded"),"Interested but not responded") -> FALSE | U34: Customer 5 - 08057410309 | V34: Pending | W34: Interested | X34: =IF(AND(W34="Interested",V34="Not Responded"),"Interested but not responded","Nil") -> Nil
K35: Customer 25 | L35: =IFERROR(TODAY()-Cleaned_Data!H30,"not_updated") -> 259 | O35: Customer 1 - 09256072034 | P35: Contacted | Q35: 76 | R35: =IF(AND(Cleaned_Data!I35="Interested",Cleaned_Data!G35="Not Responded"),"Interested but not responded") -> FALSE | U35: Customer 1 - 09256072034 | V35: Contacted | W35: Interested | X35: =IF(AND(W35="Interested",V35="Not Responded"),"Interested but not responded","Nil") -> Nil
K36: Customer 1 | L36: =IFERROR(TODAY()-Cleaned_Data!H31,"not_updated") -> 258 | O36: Customer 3 - 879307780 | P36: Closed | Q36: 69 | R36: =IF(AND(Cleaned_Data!I36="Interested",Cleaned_Data!G36="Not Responded"),"Interested but not responded") -> FALSE | U36: Customer 3 - 879307780 | V36: Closed | W36: High Budget | X36: =IF(AND(W36="Interested",V36="Not Responded"),"Interested but not responded","Nil") -> Nil
K37: Customer 24 | L37: =IFERROR(TODAY()-Cleaned_Data!H32,"not_updated") -> 263 | O37: Customer 12 - 08132565651 | P37: Not Responded | Q37: not_updated | R37: =IF(AND(Cleaned_Data!I37="Interested",Cleaned_Data!G37="Not Responded"),"Interested but not responded") -> FALSE | U37: Customer 12 - 08132565651 | V37: Not Responded | W37: Comparing Options | X37: =IF(AND(W37="Interested",V37="Not Responded"),"Interested but not responded","Nil") -> Nil
K38: Customer 5 | L38: =IFERROR(TODAY()-Cleaned_Data!H33,"not_updated") -> not_updated | R38: =IF(AND(Cleaned_Data!I38="Interested",Cleaned_Data!G38="Not Responded"),"Interested but not responded") -> FALSE
K39: Customer 1 | L39: =IFERROR(TODAY()-Cleaned_Data!H34,"not_updated") -> 265 | R39: =IF(AND(Cleaned_Data!I39="Interested",Cleaned_Data!G39="Not Responded"),"Interested but not responded") -> FALSE
K40: Customer 3 | L40: =IFERROR(TODAY()-Cleaned_Data!H35,"not_updated") -> 258 | R40: =IF(AND(Cleaned_Data!I40="Interested",Cleaned_Data!G40="Not Responded"),"Interested but not responded") -> FALSE
...

Sheet Analysis sheet
F1: Analysis sheet
A3: Leads marked “Interested” but still “Not Responded.” | F3: No. of Leads per city | I3: Days Since Last Follow-up | L3: Follow-up status pending for more than 5 days
A4: Lead_ID | B4: Follow-up Status | C4: Remarks | D4: Follow-up status flag | F4: City | G4: No. of leads | I4: Customer name | J4: Days Since Last Follow-up | L4: Lead_ID | M4: Follow-up Status | N4: Days Since Last Follow-up
A5: Customer 7 - 981207197 | B5: Closed | C5: Low Budget | D5: =IF(AND(C5="Interested",B5="Not Responded"),"Interested but not responded","Nil") -> Nil | F5: Hyderabad | G5: 10 | I5: Customer 7 | J5: 69 | L5: Customer 7 - 981207197 | M5: Closed | N5: 69
A6: Customer 11 - 316699969071 | B6: Not Responded | C6: Low Budget | D6: =IF(AND(C6="Interested",B6="Not Responded"),"Interested but not responded","Nil") -> Nil | F6: Delhi | G6: 6 | I6: Customer 11 | J6: 73 | L6: Customer 11 - 316699969071 | M6: Not Responded | N6: 73
A7: Customer 15 - 07555537329 | B7: Appointment Fixed | C7: Low Budget | D7: =IF(AND(C7="Interested",B7="Not Responded"),"Interested but not responded","Nil") -> Nil | F7: Jaipur | G7: 5 | I7: Customer 15 | J7: 74 | L7: Customer 15 - 07555537329 | M7: Appointment Fixed | N7: 74
A8: Customer 16 - 924004015 | B8: Closed | C8: Wants Callback | D8: =IF(AND(C8="Interested",B8="Not Responded"),"Interested but not responded","Nil") -> Nil | F8: Mumbai | G8: 11 | I8: Customer 16 | J8: 69 | L8: Customer 16 - 924004015 | M8: Closed | N8: 69
A9: Customer 7 - 07167705031 | B9: Contacted | C9: Low Budget | D9: =IF(AND(C9="Interested",B9="Not Responded"),"Interested but not responded","Nil") -> Nil | F9: Bangalore | G9: 3 | I9: Customer 7 | J9: 69 | L9: Customer 7 - 07167705031 | M9: Contacted | N9: 69
A10: Customer 9 - 07326304605 | B10: Not Responded | C10: Interested | D10: =IF(AND(C10="Interested",B10="Not Responded"),"Interested but not responded","Nil") -> Interested but not responded | I10: Customer 9 | J10: 67 | L10: Customer 9 - 07326304605 | M10: Not Responded | N10: 67
A11: Customer 5 - 7452200799 | B11: Pending | C11: High Budget | D11: =IF(AND(C11="Interested",B11="Not Responded"),"Interested but not responded","Nil") -> Nil | I11: Customer 5 | J11: 74 | L11: Customer 5 - 7452200799 | M11: Pending | N11: 74
A12: Customer 2 - 366479543551 | B12: Contacted | C12: High Budget | D12: =IF(AND(C12="Interested",B12="Not Responded"),"Interested but not responded","Nil") -> Nil | F12: No. of Leads by Follow-up Status | I12: Customer 2 | J12: 70 | L12: Customer 2 - 366479543551 | M12: Contacted | N12: 70
A13: Customer 25 - 7238138275 | B13: Pending | C13: Comparing Options | D13: =IF(AND(C13="Interested",B13="Not Responded"),"Interested but not responded","Nil") -> Nil | F13: Follow-up Status | G13: No. of Leads | I13: Customer 25 | J13: 74 | L13: Customer 25 - 7238138275 | M13: Pending | N13: 74
A14: Customer 2 - 294307938915 | B14: Appointment Fixed | C14: Comparing Options | D14: =IF(AND(C14="Interested",B14="Not Responded"),"Interested but not responded","Nil") -> Nil | F14: Closed | G14: 10 | I14: Customer 2 | J14: 76 | L14: Customer 2 - 294307938915 | M14: Appointment Fixed | N14: 76
A15: Customer 16 - 07719529297 | B15: Closed | C15: High Budget | D15: =IF(AND(C15="Interested",B15="Not Responded"),"Interested but not responded","Nil") -> Nil | F15: Not Responded | G15: 6 | I15: Customer 16 | J15: 76 | L15: Customer 16 - 07719529297 | M15: Closed | N15: 76
A16: Customer 16 - 237172709909 | B16: Pending | C16: Wants Callback | D16: =IF(AND(C16="Interested",B16="Not Responded"),"Interested but not responded","Nil") -> Nil | F16: Appointment Fixed | G16: 2 | I16: Customer 16 | J16: 75 | L16: Customer 16 - 237172709909 | M16: Pending | N16: 75
A17: Customer 7 - 9654384657 | B17: Contacted | C17: Comparing Options | D17: =IF(AND(C17="Interested",B17="Not Responded"),"Interested but not responded","Nil") -> Nil | F17: Contacted | G17: 9 | I17: Customer 7 | J17: 74 | L17: Customer 7 - 9654384657 | M17: Contacted | N17: 74
A18: Customer 8 - 117040380882 | B18: Closed | C18: Comparing Options | D18: =IF(AND(C18="Interested",B18="Not Responded"),"Interested but not responded","Nil") -> Nil | F18: Pending | G18: 8 | I18: Customer 8 | J18: 74 | L18: Customer 8 - 117040380882 | M18: Closed | N18: 74
A19: Customer 2 - 8676078088 | B19: Contacted | C19: Interested | D19: =IF(AND(C19="Interested",B19="Not Responded"),"Interested but not responded","Nil") -> Nil | I19: Customer 2 | J19: 70 | L19: Customer 2 - 8676078088 | M19: Contacted | N19: 70
A20: Customer 1 - 8321936663 | B20: Not Responded | C20: Wants Callback | D20: =IF(AND(C20="Interested",B20="Not Responded"),"Interested but not responded","Nil") -> Nil | I20: Customer 1 | J20: 74 | L20: Customer 1 - 8321936663 | M20: Not Responded | N20: 74
A21: Customer 1 - 969140392131 | B21: Closed | C21: Low Budget | D21: =IF(AND(C21="Interested",B21="Not Responded"),"Interested but not responded","Nil") -> Nil | F21: % Conversion Rate per city | I21: Customer 1 | J21: 76 | L21: Customer 1 - 969140392131 | M21: Closed | N21: 76
A22: Customer 16 - 7541729247 | B22: Pending | C22: Wants Callback | D22: =IF(AND(C22="Interested",B22="Not Responded"),"Interested but not responded","Nil") -> Nil | F22: City | G22: % Conversion Rate | I22: Customer 16 | J22: 71 | L22: Customer 16 - 7541729247 | M22: Pending | N22: 71
A23: Customer 6 - 09411182015 | B23: Not Responded | C23: Wants Callback | D23: =IF(AND(C23="Interested",B23="Not Responded"),"Interested but not responded","Nil") -> Nil | F23: Hyderabad | G23: 0.5 | I23: Customer 6 | J23: 67 | L23: Customer 6 - 09411182015 | M23: Not Responded | N23: 67
A24: Customer 21 - 184634638538 | B24: Closed | C24: Wants Callback | D24: =IF(AND(C24="Interested",B24="Not Responded"),"Interested but not responded","Nil") -> Nil | F24: Delhi | G24: 0.16666667 | I24: Customer 21 | J24: not_updated | L24: Customer 21 - 184634638538 | M24: Closed | N24: not_updated
A25: Customer 20 - 07857711890 | B25: Contacted | C25: Comparing Options | D25: =IF(AND(C25="Interested",B25="Not Responded"),"Interested but not responded","Nil") -> Nil | F25: Jaipur | G25: 0 | I25: Customer 20 | J25: 77 | L25: Customer 20 - 07857711890 | M25: Contacted | N25: 77
A26: Customer 11 - 9705030412 | B26: Pending | C26: Wants Callback | D26: =IF(AND(C26="Interested",B26="Not Responded"),"Interested but not responded","Nil") -> Nil | F26: Mumbai | G26: 0.18181818 | I26: Customer 11 | J26: 77 | L26: Customer 11 - 9705030412 | M26: Pending | N26: 77
A27: Customer 6 - 890030316 | B27: Contacted | C27: Comparing Options | D27: =IF(AND(C27="Interested",B27="Not Responded"),"Interested but not responded","Nil") -> Nil | F27: Bangalore | G27: 0.66666667 | I27: Customer 6 | J27: 69 | L27: Customer 6 - 890030316 | M27: Contacted | N27: 69
A28: Customer 5 - 9426142443 | B28: Contacted | C28: Interested | D28: =IF(AND(C28="Interested",B28="Not Responded"),"Interested but not responded","Nil") -> Nil | I28: Customer 5 | J28: 71 | L28: Customer 5 - 9426142443 | M28: Contacted | N28: 71
A29: Customer 6 - 805352028 | B29: Closed | C29: High Budget | D29: =IF(AND(C29="Interested",B29="Not Responded"),"Interested but not responded","Nil") -> Nil | I29: Customer 6 | J29: 70 | L29: Customer 6 - 805352028 | M29: Closed | N29: 70
A30: Customer 22 - 8966036820 | B30: Pending | C30: Low Budget | D30: =IF(AND(C30="Interested",B30="Not Responded"),"Interested but not responded","Nil") -> Nil | I30: Customer 22 | J30: 67 | L30: Customer 22 - 8966036820 | M30: Pending | N30: 67
A31: Customer 9 - 8890833782 | B31: Contacted | C31: Comparing Options | D31: =IF(AND(C31="Interested",B31="Not Responded"),"Interested but not responded","Nil") -> Nil | I31: Customer 9 | J31: 73 | L31: Customer 9 - 8890833782 | M31: Contacted | N31: 73
A32: Customer 25 - 969752546 | B32: Closed | C32: High Budget | D32: =IF(AND(C32="Interested",B32="Not Responded"),"Interested but not responded","Nil") -> Nil | I32: Customer 25 | J32: 71 | L32: Customer 25 - 969752546 | M32: Closed | N32: 71
A33: Customer 25 - 07752644151 | B33: Closed | C33: Interested | D33: =IF(AND(C33="Interested",B33="Not Responded"),"Interested but not responded","Nil") -> Nil | I33: Customer 25 | J33: 70 | L33: Customer 25 - 07752644151 | M33: Closed | N33: 70
A34: Customer 1 - 705363184 | B34: Pending | C34: Comparing Options | D34: =IF(AND(C34="Interested",B34="Not Responded"),"Interested but not responded","Nil") -> Nil | I34: Customer 1 | J34: 69 | L34: Customer 1 - 705363184 | M34: Pending | N34: 69
A35: Customer 24 - 927038743 | B35: Not Responded | C35: Interested | D35: =IF(AND(C35="Interested",B35="Not Responded"),"Interested but not responded","Nil") -> Interested but not responded | I35: Customer 24 | J35: 74 | L35: Customer 24 - 927038743 | M35: Not Responded | N35: 74
A36: Customer 5 - 08057410309 | B36: Pending | C36: Interested | D36: =IF(AND(C36="Interested",B36="Not Responded"),"Interested but not responded","Nil") -> Nil | I36: Customer 5 | J36: not_updated | L36: Customer 5 - 08057410309 | M36: Pending | N36: not_updated
A37: Customer 1 - 09256072034 | B37: Contacted | C37: Interested | D37: =IF(AND(C37="Interested",B37="Not Responded"),"Interested but not responded","Nil") -> Nil | I37: Customer 1 | J37: 76 | L37: Customer 1 - 09256072034 | M37: Contacted | N37: 76
A38: Customer 3 - 879307780 | B38: Closed | C38: High Budget | D38: =IF(AND(C38="Interested",B38="Not Responded"),"Interested but not responded","Nil") -> Nil | I38: Customer 3 | J38: 69 | L38: Customer 3 - 879307780 | M38: Closed | N38: 69
A39: Customer 12 - 08132565651 | B39: Not Responded | C39: Comparing Options | D39: =IF(AND(C39="Interested",B39="Not Responded"),"Interested but not responded","Nil") -> Nil | I39: Customer 12 | J39: not_updated | L39: Customer 12 - 08132565651 | M39: Not Responded | N39: not_updated

Sheet Working Sheet 3
A24: Row Labels | B24: Row Labels
A25: Jaipur | B25: Bangalore | C25: =D16/L16 -> #DIV/0!
A26: Bangalore | B26: Delhi | C26: =D17/L17 -> #DIV/0!
A27: Bengluru | B27: Hyderabad | C27: =D18/L18 -> #DIV/0!
A28: Delhi | B28: Jaipur | C28: =D19/L19 -> #DIV/0!
A29: Hyd | B29: Mumbai | C29: =D20/L20 -> #DIV/0!
A30: Hyderabad
A31: Jaipur
A32: Mumabi
A33: Mumbai
A34: Grand Total

Sheet Dashboard Sheet
I1: Dashboard
